Workbook

Sheet Cover Sheet
B3: Sales data - Transformed data
B7: This workbook contains the intermediate solution for the Sales data exercise. Sheet 1 "Sales data" contains the data we obtained from our friend. Sheet 2 "Sales data - transf.+validated" contains the transformed sales data.

Sheet Sales data
A1: This sheet contains the data we obtained from our friend
B3: Sales data October to December 2018
B4: Soest
B5: Winter
B6: Category | C6: Item | D6: Reduced price? | E6: Items sold | F6: Price
B7: Ski | C7: Salomon Ski | D7: No | E7: 56 | F7: 499.99
D8: Yes | E8: 12 | F8: 399.99
C9: Head Ski | D9: No | E9: 32 | F9: 449.99
D10: Yes | E10: 24 | F10: 399.99
C11: Atomic Ski | D11: No | E11: 36 | F11: 474.99
D12: Yes | E12: 2 | F12: 449.99
B13: Bindings | C13: Salomon Binding | D13: No | E13: 60 | F13: 99.99
C14: Head Bindings | D14: No | E14: 40 | F14: 99.99
D15: Yes | E15: 17 | F15: 79.99
B16: Boots | C16: Lange Boots | D16: No | E16: 33 | F16: 299.99
C17: Head Boots | D17: No | E17: 24 | F17: 249.99
D18: Yes | E18: 8 | F18: 199.99
B19: Summer
B20: Bikes | C20: Giant | D20: No | E20: 24 | F20: 699.99
D21: Yes | E21: 24 | F21: 599.99
C22: Yeti | D22: No | E22: 12 | F22: 899.99
D23: Yes | E23: 2 | F23: 799.99
C24: GT Bicycles | D24: No | E24: 28 | F24: 599.99
D25: Yes | E25: 14 | F25: 499.99
C26: Cannondale | D26: No | E26: 4 | F26: 3999.99
D27: Yes | E27: 1 | F27: 3799.99
B29: Winterberg
B30: Winter
B31: Category | C31: Item | D31: Reduced price? | E31: Items sold | F31: Price
B32: Ski | C32: Salomon Ski | D32: No | E32: 46 | F32: 499.99
D33: Yes | E33: 11 | F33: 399.99
C34: Head Ski | D34: No | E34: 28 | F34: 449.99
D35: Yes | E35: 21 | F35: 399.99
C36: Atomic Ski | D36: No | E36: 33 | F36: 474.99
D37: Yes | E37: 3 | F37: 449.99
B38: Bindings | C38: Salomon Binding | D38: No | E38: 58 | F38: 99.99
C39: Head Bindings | D39: No | E39: 33 | F39: 99.99
D40: Yes | E40: 24 | F40: 79.99
B41: Boots | C41: Lange Boots | D41: No | E41: 25 | F41: 299.99
D42: Yes | E42: 7 | F42: 274.99
...

Sheet Sales data - transf.+validated
A1: This sheet contains the transformed sales data in database format, including data validation
B3: Sales data October to December 2018
B4: Location | C4: Season | D4: Category | E4: Item | F4: Items sold at original price | G4: Original price | H4: Items sold at reduced price | I4: Reduced price | J4: Total sales in original price | K4: Total sales in reduced price | L4: Total sales | M4: Price Reduction | N4: Unit cost | O4: Total costs
B5: Soest | C5: Winter | D5: Ski | E5: Salomon Ski | F5: 56 | G5: 499.99 | H5: 12 | I5: 399.99 | J5: =F5*G5 -> 27999.44 | K5: =H5*I5 -> 4799.88 | L5: =J5+K5 -> 32799.32 | M5: =IFERROR(IF(I5=0,0,(G5-I5)/G5),0) | N5: =VLOOKUP(E5,'Additional data'!$B$5:$C$16,2,FALSE) | O5: =(F5+H5)*N5
B6: Soest | C6: Winter | D6: Ski | E6: Head Ski | F6: 32 | G6: 449.99 | H6: 24 | I6: 399.99 | J6: =F6*G6 -> 14399.68 | K6: =H6*I6 -> 9599.76 | L6: =J6+K6 -> 23999.44 | M6: =IFERROR(IF(I6=0,0,(G6-I6)/G6),0) | N6: =VLOOKUP(E6,'Additional data'!$B$5:$C$16,2,FALSE) | O6: =(F6+H6)*N6
B7: Soest | C7: Winter | D7: Ski | E7: Atomic Ski | F7: 36 | G7: 474.99 | H7: 2 | I7: 449.99 | J7: =F7*G7 -> 17099.64 | K7: =H7*I7 -> 899.98 | L7: =J7+K7 -> 17999.62 | M7: =IFERROR(IF(I7=0,0,(G7-I7)/G7),0) | N7: =VLOOKUP(E7,'Additional data'!$B$5:$C$16,2,FALSE) | O7: =(F7+H7)*N7
B8: Soest | C8: Winter | D8: Bindings | E8: Salomon Binding | F8: 60 | G8: 99.99 | H8: 0 | J8: =F8*G8 -> 5999.4 | K8: =H8*I8 -> 0 | L8: =J8+K8 -> 5999.4 | M8: =IFERROR(IF(I8=0,0,(G8-I8)/G8),0) | N8: =VLOOKUP(E8,'Additional data'!$B$5:$C$16,2,FALSE) | O8: =(F8+H8)*N8
B9: Soest | C9: Winter | D9: Bindings | E9: Head Bindings | F9: 40 | G9: 99.99 | H9: 17 | I9: 79.99 | J9: =F9*G9 -> 3999.6 | K9: =H9*I9 -> 1359.83 | L9: =J9+K9 -> 5359.43 | M9: =IFERROR(IF(I9=0,0,(G9-I9)/G9),0) | N9: =VLOOKUP(E9,'Additional data'!$B$5:$C$16,2,FALSE) | O9: =(F9+H9)*N9
B10: Soest | C10: Winter | D10: Boots | E10: Lange Boots | F10: 33 | G10: 299.99 | H10: 0 | J10: =F10*G10 -> 9899.67 | K10: =H10*I10 -> 0 | L10: =J10+K10 -> 9899.67 | M10: =IFERROR(IF(I10=0,0,(G10-I10)/G10),0) | N10: =VLOOKUP(E10,'Additional data'!$B$5:$C$16,2,FALSE) | O10: =(F10+H10)*N10
B11: Soest | C11: Winter | D11: Boots | E11: Head Boots | F11: 24 | G11: 249.99 | H11: 8 | I11: 199.99 | J11: =F11*G11 -> 5999.76 | K11: =H11*I11 -> 1599.92 | L11: =J11+K11 -> 7599.68 | M11: =IFERROR(IF(I11=0,0,(G11-I11)/G11),0) | N11: =VLOOKUP(E11,'Additional data'!$B$5:$C$16,2,FALSE) | O11: =(F11+H11)*N11
B12: Soest | C12: Summer | D12: Bikes | E12: Giant | F12: 24 | G12: 699.99 | H12: 24 | I12: 599.99 | J12: =F12*G12 -> 16799.76 | K12: =H12*I12 -> 14399.76 | L12: =J12+K12 -> 31199.52 | M12: =IFERROR(IF(I12=0,0,(G12-I12)/G12),0) | N12: =VLOOKUP(E12,'Additional data'!$B$5:$C$16,2,FALSE) | O12: =(F12+H12)*N12
B13: Soest | C13: Summer | D13: Bikes | E13: Yeti | F13: 12 | G13: 899.99 | H13: 2 | I13: 799.99 | J13: =F13*G13 -> 10799.88 | K13: =H13*I13 -> 1599.98 | L13: =J13+K13 -> 12399.86 | M13: =IFERROR(IF(I13=0,0,(G13-I13)/G13),0) | N13: =VLOOKUP(E13,'Additional data'!$B$5:$C$16,2,FALSE) | O13: =(F13+H13)*N13
B14: Soest | C14: Summer | D14: Bikes | E14: GT Bicycles | F14: 28 | G14: 599.99 | H14: 14 | I14: 499.99 | J14: =F14*G14 -> 16799.72 | K14: =H14*I14 -> 6999.86 | L14: =J14+K14 -> 23799.58 | M14: =IFERROR(IF(I14=0,0,(G14-I14)/G14),0) | N14: =VLOOKUP(E14,'Additional data'!$B$5:$C$16,2,FALSE) | O14: =(F14+H14)*N14
B15: Soest | C15: Summer | D15: Bikes | E15: Cannondale | F15: 4 | G15: 3999.99 | H15: 1 | I15: 3799.99 | J15: =F15*G15 -> 15999.96 | K15: =H15*I15 -> 3799.99 | L15: =J15+K15 -> 19799.95 | M15: =IFERROR(IF(I15=0,0,(G15-I15)/G15),0) | N15: =VLOOKUP(E15,'Additional data'!$B$5:$C$16,2,FALSE) | O15: =(F15+H15)*N15
B16: Winterberg | C16: Winter | D16: Ski | E16: Salomon Ski | F16: 46 | G16: 499.99 | H16: 11 | I16: 399.99 | J16: =F16*G16 -> 22999.54 | K16: =H16*I16 -> 4399.89 | L16: =J16+K16 -> 27399.43 | M16: =IFERROR(IF(I16=0,0,(G16-I16)/G16),0) | N16: =VLOOKUP(E16,'Additional data'!$B$5:$C$16,2,FALSE) | O16: =(F16+H16)*N16
B17: Winterberg | C17: Winter | D17: Ski | E17: Head Ski | F17: 28 | G17: 449.99 | H17: 21 | I17: 399.99 | J17: =F17*G17 -> 12599.72 | K17: =H17*I17 -> 8399.79 | L17: =J17+K17 -> 20999.51 | M17: =IFERROR(IF(I17=0,0,(G17-I17)/G17),0) | N17: =VLOOKUP(E17,'Additional data'!$B$5:$C$16,2,FALSE) | O17: =(F17+H17)*N17
B18: Winterberg | C18: Winter | D18: Ski | E18: Atomic Ski | F18: 33 | G18: 474.99 | H18: 3 | I18: 449.99 | J18: =F18*G18 -> 15674.67 | K18: =H18*I18 -> 1349.97 | L18: =J18+K18 -> 17024.64 | M18: =IFERROR(IF(I18=0,0,(G18-I18)/G18),0) | N18: =VLOOKUP(E18,'Additional data'!$B$5:$C$16,2,FALSE) | O18: =(F18+H18)*N18
B19: Winterberg | C19: Winter | D19: Bindings | E19: Salomon Binding | F19: 58 | G19: 99.99 | H19: 0 | J19: =F19*G19 -> 5799.42 | K19: =H19*I19 -> 0 | L19: =J19+K19 -> 5799.42 | M19: =IFERROR(IF(I19=0,0,(G19-I19)/G19),0) | N19: =VLOOKUP(E19,'Additional data'!$B$5:$C$16,2,FALSE) | O19: =(F19+H19)*N19
B20: Winterberg | C20: Winter | D20: Bindings | E20: Head Bindings | F20: 33 | G20: 99.99 | H20: 24 | I20: 79.99 | J20: =F20*G20 -> 3299.67 | K20: =H20*I20 -> 1919.76 | L20: =J20+K20 -> 5219.43 | M20: =IFERROR(IF(I20=0,0,(G20-I20)/G20),0) | N20: =VLOOKUP(E20,'Additional data'!$B$5:$C$16,2,FALSE) | O20: =(F20+H20)*N20
B21: Winterberg | C21: Winter | D21: Boots | E21: Lange Boots | F21: 25 | G21: 299.99 | H21: 7 | I21: 274.99 | J21: =F21*G21 -> 7499.75 | K21: =H21*I21 -> 1924.93 | L21: =J21+K21 -> 9424.68 | M21: =IFERROR(IF(I21=0,0,(G21-I21)/G21),0) | N21: =VLOOKUP(E21,'Additional data'!$B$5:$C$16,2,FALSE) | O21: =(F21+H21)*N21
B22: Winterberg | C22: Winter | D22: Boots | E22: Head Boots | F22: 18 | G22: 249.99 | H22: 7 | I22: 199.99 | J22: =F22*G22 -> 4499.82 | K22: =H22*I22 -> 1399.93 | L22: =J22+K22 -> 5899.75 | M22: =IFERROR(IF(I22=0,0,(G22-I22)/G22),0) | N22: =VLOOKUP(E22,'Additional data'!$B$5:$C$16,2,FALSE) | O22: =(F22+H22)*N22
B23: Winterberg | C23: Summer | D23: Bikes | E23: Giant | F23: 14 | G23: 699.99 | H23: 0 | J23: =F23*G23 -> 9799.86 | K23: =H23*I23 -> 0 | L23: =J23+K23 -> 9799.86 | M23: =IFERROR(IF(I23=0,0,(G23-I23)/G23),0) | N23: =VLOOKUP(E23,'Additional data'!$B$5:$C$16,2,FALSE) | O23: =(F23+H23)*N23
B24: Winterberg | C24: Summer | D24: Bikes | E24: Yeti | F24: 11 | G24: 899.99 | H24: 4 | I24: 749.99 | J24: =F24*G24 -> 9899.89 | K24: =H24*I24 -> 2999.96 | L24: =J24+K24 -> 12899.85 | M24: =IFERROR(IF(I24=0,0,(G24-I24)/G24),0) | N24: =VLOOKUP(E24,'Additional data'!$B$5:$C$16,2,FALSE) | O24: =(F24+H24)*N24
B25: Winterberg | C25: Summer | D25: Bikes | E25: GT Bicycles | F25: 15 | G25: 599.99 | H25: 4 | I25: 539.99 | J25: =F25*G25 -> 8999.85 | K25: =H25*I25 -> 2159.96 | L25: =J25+K25 -> 11159.81 | M25: =IFERROR(IF(I25=0,0,(G25-I25)/G25),0) | N25: =VLOOKUP(E25,'Additional data'!$B$5:$C$16,2,FALSE) | O25: =(F25+H25)*N25
B26: Hamm | C26: Winter | D26: Ski | E26: Salomon Ski | F26: 14 | G26: 499.99 | H26: 0 | J26: =F26*G26 -> 6999.86 | K26: =H26*I26 -> 0 | L26: =J26+K26 -> 6999.86 | M26: =IFERROR(IF(I26=0,0,(G26-I26)/G26),0) | N26: =VLOOKUP(E26,'Additional data'!$B$5:$C$16,2,FALSE) | O26: =(F26+H26)*N26
B27: Hamm | C27: Winter | D27: Ski | E27: Stöckli Ski | F27: 3 | G27: 1099.99 | H27: 1 | I27: 999.99 | J27: =F27*G27 -> 3299.97 | K27: =H27*I27 -> 999.99 | L27: =J27+K27 -> 4299.96 | M27: =IFERROR(IF(I27=0,0,(G27-I27)/G27),0) | N27: =VLOOKUP(E27,'Additional data'!$B$5:$C$16,2,FALSE) | O27: =(F27+H27)*N27
B28: Hamm | C28: Winter | D28: Bindings | E28: Salomon Binding | F28: 7 | G28: 99.99 | H28: 0 | J28: =F28*G28 -> 699.93 | K28: =H28*I28 -> 0 | L28: =J28+K28 -> 699.93 | M28: =IFERROR(IF(I28=0,0,(G28-I28)/G28),0) | N28: =VLOOKUP(E28,'Additional data'!$B$5:$C$16,2,FALSE) | O28: =(F28+H28)*N28
B29: Hamm | C29: Winter | D29: Bindings | E29: Head Bindings | F29: 3 | G29: 99.99 | H29: 6 | I29: 79.99 | J29: =F29*G29 -> 299.97 | K29: =H29*I29 -> 479.94 | L29: =J29+K29 -> 779.91 | M29: =IFERROR(IF(I29=0,0,(G29-I29)/G29),0) | N29: =VLOOKUP(E29,'Additional data'!$B$5:$C$16,2,FALSE) | O29: =(F29+H29)*N29
B30: Hamm | C30: Winter | D30: Boots | E30: Lange Boots | F30: 4 | G30: 299.99 | H30: 0 | J30: =F30*G30 -> 1199.96 | K30: =H30*I30 -> 0 | L30: =J30+K30 -> 1199.96 | M30: =IFERROR(IF(I30=0,0,(G30-I30)/G30),0) | N30: =VLOOKUP(E30,'Additional data'!$B$5:$C$16,2,FALSE) | O30: =(F30+H30)*N30
B31: Hamm | C31: Winter | D31: Boots | E31: Head Boots | F31: 0 | H31: 2 | I31: 199.99 | J31: =F31*G31 -> 0 | K31: =H31*I31 -> 399.98 | L31: =J31+K31 -> 399.98 | M31: =IFERROR(IF(I31=0,0,(G31-I31)/G31),0) | N31: =VLOOKUP(E31,'Additional data'!$B$5:$C$16,2,FALSE) | O31: =(F31+H31)*N31
B32: Hamm | C32: Summer | D32: Bikes | E32: Giant | F32: 18 | G32: 699.99 | H32: 11 | I32: 599.99 | J32: =F32*G32 -> 12599.82 | K32: =H32*I32 -> 6599.89 | L32: =J32+K32 -> 19199.71 | M32: =IFERROR(IF(I32=0,0,(G32-I32)/G32),0) | N32: =VLOOKUP(E32,'Additional data'!$B$5:$C$16,2,FALSE) | O32: =(F32+H32)*N32
B33: Hamm | C33: Summer | D33: Bikes | E33: Yeti | F33: 16 | G33: 899.99 | H33: 12 | I33: 799.99 | J33: =F33*G33 -> 14399.84 | K33: =H33*I33 -> 9599.88 | L33: =J33+K33 -> 23999.72 | M33: =IFERROR(IF(I33=0,0,(G33-I33)/G33),0) | N33: =VLOOKUP(E33,'Additional data'!$B$5:$C$16,2,FALSE) | O33: =(F33+H33)*N33
B34: Hamm | C34: Summer | D34: Bikes | E34: GT Bicycles | F34: 26 | G34: 599.99 | H34: 13 | I34: 499.99 | J34: =F34*G34 -> 15599.74 | K34: =H34*I34 -> 6499.87 | L34: =J34+K34 -> 22099.61 | M34: =IFERROR(IF(I34=0,0,(G34-I34)/G34),0) | N34: =VLOOKUP(E34,'Additional data'!$B$5:$C$16,2,FALSE) | O34: =(F34+H34)*N34
B35: Hamm | C35: Summer | D35: Bikes | E35: Cannondale | F35: 5 | G35: 3999.99 | H35: 2 | I35: 3799.99 | J35: =F35*G35 -> 19999.95 | K35: =H35*I35 -> 7599.98 | L35: =J35+K35 -> 27599.93 | M35: =IFERROR(IF(I35=0,0,(G35-I35)/G35),0) | N35: =VLOOKUP(E35,'Additional data'!$B$5:$C$16,2,FALSE) | O35: =(F35+H35)*N35

Sheet results
C2: Soest | D2: Winterberg | E2: Hamm
B3: Revenue | C3: =SUMIF('Sales data - transf.+validated'!$B$5:$B$35,results!C$2,'Sales data - transf.+validated'!$L$5:$L$35) -> 190855.47 | D3: =SUMIF('Sales data - transf.+validated'!$B$5:$B$35,results!D$2,'Sales data - transf.+validated'!$L$5:$L$35) -> 125626.38 | E3: =SUMIF('Sales data - transf.+validated'!$B$5:$B$35,results!E$2,'Sales data - transf.+validated'!$L$5:$L$35) -> 107278.57
B4: Original price revenue | C4: =SUMIF('Sales data - transf.+validated'!$B$5:$B$35,results!C$2,'Sales data - transf.+validated'!$J$5:$J$35) -> 145796.51 | D4: =SUMIF('Sales data - transf.+validated'!$B$5:$B$35,results!D$2,'Sales data - transf.+validated'!$J$5:$J$35) -> 101072.19 | E4: =SUMIF('Sales data - transf.+validated'!$B$5:$B$35,results!E$2,'Sales data - transf.+validated'!$J$5:$J$35) -> 75099.04
B5: Reduced price revenue | C5: =SUMIF('Sales data - transf.+validated'!$B$5:$B$35,results!C$2,'Sales data - transf.+validated'!$K$5:$K$35) -> 45058.96 | D5: =SUMIF('Sales data - transf.+validated'!$B$5:$B$35,results!D$2,'Sales data - transf.+validated'!$K$5:$K$35) -> 24554.19 | E5: =SUMIF('Sales data - transf.+validated'!$B$5:$B$35,results!E$2,'Sales data - transf.+validated'!$K$5:$K$35) -> 32179.53

Sheet result II
C4: Location | D4: Season | E4: Total revenue | F4: Original price revenue | G4: Reduced price revenue | H4: Total costs | I4: Total contribution margin | J4: Total contribution margin per m²
C5: All locations | D5: All season | E5: =F5+G5 -> 423760.42 | F5: =SUM('Sales data - transf.+validated'!$J5:$J35) -> 321967.74 | G5: =SUM('Sales data - transf.+validated'!K5:K35) -> 101792.68 | H5: =SUMIFS('Sales data - transf.+validated'!$O$5:$O$35,'Sales data - transf.+validated'!$B$5:$B$35,IF($C5="All locations","*",$C5),'Sales data - transf.+validated'!$C$5:$C$35,IF($D5="All season","*",$D5)) | I5: =E5-H5 -> 176100.42 | J5: =I5/IF($C5="All locations",SUM('Additional data'!$F$5:$F$7),VLOOKUP('result II'!$C5,'Additional data'!$E$5:$F$7,2,FALSE)) -> 506.7638
C6: All locations | D6: Winter | E6: =F6+G6 -> 209803.02 | F6: =SUMIF('Sales data - transf.+validated'!$C$5:$C$35,'result II'!$D6,'Sales data - transf.+validated'!J$5:J$35) -> 170269.47 | G6: =SUMIF('Sales data - transf.+validated'!$C$5:$C$35,$D6,'Sales data - transf.+validated'!K$5:K$35) | H6: =SUMIFS('Sales data - transf.+validated'!$O$5:$O$35,'Sales data - transf.+validated'!$B$5:$B$35,IF($C6="All locations","*",$C6),'Sales data - transf.+validated'!$C$5:$C$35,IF($D6="All season","*",$D6)) | I6: =E6-H6 -> 90893.02 | J6: =I6/IF($C6="All locations",SUM('Additional data'!$F$5:$F$7),VLOOKUP('result II'!$C6,'Additional data'!$E$5:$F$7,2,FALSE)) -> 261.56265
C7: All locations | D7: Summer | E7: =F7+G7 -> 213957.4 | F7: =SUMIF('Sales data - transf.+validated'!$C$5:$C$35,'result II'!$D7,'Sales data - transf.+validated'!J$5:J$35) -> 151698.27 | G7: =SUMIF('Sales data - transf.+validated'!$C$5:$C$35,$D7,'Sales data - transf.+validated'!K$5:K$35) | H7: =SUMIFS('Sales data - transf.+validated'!$O$5:$O$35,'Sales data - transf.+validated'!$B$5:$B$35,IF($C7="All locations","*",$C7),'Sales data - transf.+validated'!$C$5:$C$35,IF($D7="All season","*",$D7)) | I7: =E7-H7 -> 85207.4 | J7: =I7/IF($C7="All locations",SUM('Additional data'!$F$5:$F$7),VLOOKUP('result II'!$C7,'Additional data'!$E$5:$F$7,2,FALSE)) -> 245.20115
C8: Soest | D8: All season | E8: =F8+G8 -> 190855.47 | F8: =SUMIF('Sales data - transf.+validated'!$B$5:$B$35,'result II'!$C8,'Sales data - transf.+validated'!J$5:J$35) -> 145796.51 | G8: =SUMIF('Sales data - transf.+validated'!$B$5:$B$35,'result II'!$C8,'Sales data - transf.+validated'!K$5:K$35) -> 45058.96 | H8: =SUMIFS('Sales data - transf.+validated'!$O$5:$O$35,'Sales data - transf.+validated'!$B$5:$B$35,IF($C8="All locations","*",$C8),'Sales data - transf.+validated'!$C$5:$C$35,IF($D8="All season","*",$D8)) | I8: =E8-H8 -> 78645.47 | J8: =I8/IF($C8="All locations",SUM('Additional data'!$F$5:$F$7),VLOOKUP('result II'!$C8,'Additional data'!$E$5:$F$7,2,FALSE)) -> 604.96515
C9: Soest | D9: Winter | E9: =F9+G9 -> 103656.56 | F9: =SUMIFS('Sales data - transf.+validated'!J$5:J$35,'Sales data - transf.+validated'!$B$5:$B$35,'result II'!$C9,'Sales data - transf.+validated'!$C$5:$C$35,'result II'!$D9) -> 85397.19 | G9: =SUMIFS('Sales data - transf.+validated'!K$5:K$35,'Sales data - transf.+validated'!$B$5:$B$35,'result II'!$C9,'Sales data - transf.+validated'!$C$5:$C$35,'result II'!$D9) -> 18259.37 | H9: =SUMIFS('Sales data - transf.+validated'!$O$5:$O$35,'Sales data - transf.+validated'!$B$5:$B$35,IF($C9="All locations","*",$C9),'Sales data - transf.+validated'!$C$5:$C$35,IF($D9="All season","*",$D9)) | I9: =E9-H9 -> 45846.56 | J9: =I9/IF($C9="All locations",SUM('Additional data'!$F$5:$F$7),VLOOKUP('result II'!$C9,'Additional data'!$E$5:$F$7,2,FALSE)) -> 352.66585
C10: Soest | D10: Summer | E10: =F10+G10 -> 87198.91 | F10: =SUMIFS('Sales data - transf.+validated'!J$5:J$35,'Sales data - transf.+validated'!$B$5:$B$35,'result II'!$C10,'Sales data - transf.+validated'!$C$5:$C$35,'result II'!$D10) -> 60399.32 | G10: =SUMIFS('Sales data - transf.+validated'!K$5:K$35,'Sales data - transf.+validated'!$B$5:$B$35,'result II'!$C10,'Sales data - transf.+validated'!$C$5:$C$35,'result II'!$D10) -> 26799.59 | H10: =SUMIFS('Sales data - transf.+validated'!$O$5:$O$35,'Sales data - transf.+validated'!$B$5:$B$35,IF($C10="All locations","*",$C10),'Sales data - transf.+validated'!$C$5:$C$35,IF($D10="All season","*",$D10)) | I10: =E10-H10 -> 32798.91 | J10: =I10/IF($C10="All locations",SUM('Additional data'!$F$5:$F$7),VLOOKUP('result II'!$C10,'Additional data'!$E$5:$F$7,2,FALSE)) -> 252.29931
C11: Winterberg | D11: All season | E11: =F11+G11 -> 125626.38 | F11: =SUMIF('Sales data - transf.+validated'!$B$5:$B$35,'result II'!$C$11,'Sales data - transf.+validated'!J$5:J$35) -> 101072.19 | G11: =SUMIF('Sales data - transf.+validated'!$B$5:$B$35,'result II'!$C$11,'Sales data - transf.+validated'!K$5:K$35) -> 24554.19 | H11: =SUMIFS('Sales data - transf.+validated'!$O$5:$O$35,'Sales data - transf.+validated'!$B$5:$B$35,IF($C11="All locations","*",$C11),'Sales data - transf.+validated'!$C$5:$C$35,IF($D11="All season","*",$D11)) | I11: =E11-H11 -> 53526.38 | J11: =I11/IF($C11="All locations",SUM('Additional data'!$F$5:$F$7),VLOOKUP('result II'!$C11,'Additional data'!$E$5:$F$7,2,FALSE)) -> 557.56646
C12: Winterberg | D12: Winter | E12: =F12+G12 -> 91766.86 | F12: =SUMIFS('Sales data - transf.+validated'!J$5:J$35,'Sales data - transf.+validated'!$B$5:$B$35,'result II'!$C12,'Sales data - transf.+validated'!$C$5:$C$35,'result II'!$D12) -> 72372.59 | G12: =SUMIFS('Sales data - transf.+validated'!K$5:K$35,'Sales data - transf.+validated'!$B$5:$B$35,'result II'!$C12,'Sales data - transf.+validated'!$C$5:$C$35,'result II'!$D12) -> 19394.27 | H12: =SUMIFS('Sales data - transf.+validated'!$O$5:$O$35,'Sales data - transf.+validated'!$B$5:$B$35,IF($C12="All locations","*",$C12),'Sales data - transf.+validated'!$C$5:$C$35,IF($D12="All season","*",$D12)) | I12: =E12-H12 -> 39116.86 | J12: =I12/IF($C12="All locations",SUM('Additional data'!$F$5:$F$7),VLOOKUP('result II'!$C12,'Additional data'!$E$5:$F$7,2,FALSE)) -> 407.46729
C13: Winterberg | D13: Summer | E13: =F13+G13 -> 33859.52 | F13: =SUMIFS('Sales data - transf.+validated'!J$5:J$35,'Sales data - transf.+validated'!$B$5:$B$35,'result II'!$C13,'Sales data - transf.+validated'!$C$5:$C$35,'result II'!$D13) -> 28699.6 | G13: =SUMIFS('Sales data - transf.+validated'!K$5:K$35,'Sales data - transf.+validated'!$B$5:$B$35,'result II'!$C13,'Sales data - transf.+validated'!$C$5:$C$35,'result II'!$D13) -> 5159.92 | H13: =SUMIFS('Sales data - transf.+validated'!$O$5:$O$35,'Sales data - transf.+validated'!$B$5:$B$35,IF($C13="All locations","*",$C13),'Sales data - transf.+validated'!$C$5:$C$35,IF($D13="All season","*",$D13)) | I13: =E13-H13 -> 14409.52 | J13: =I13/IF($C13="All locations",SUM('Additional data'!$F$5:$F$7),VLOOKUP('result II'!$C13,'Additional data'!$E$5:$F$7,2,FALSE)) -> 150.09917
C14: Hamm | D14: All season | E14: =F14+G14 -> 107278.57 | F14: =SUMIF('Sales data - transf.+validated'!$B$5:$B$35,'result II'!$C14,'Sales data - transf.+validated'!J$5:J$35) -> 75099.04 | G14: =SUMIF('Sales data - transf.+validated'!$B$5:$B$35,'result II'!$C14,'Sales data - transf.+validated'!K$5:K$35) -> 32179.53 | H14: =SUMIFS('Sales data - transf.+validated'!$O$5:$O$35,'Sales data - transf.+validated'!$B$5:$B$35,IF($C14="All locations","*",$C14),'Sales data - transf.+validated'!$C$5:$C$35,IF($D14="All season","*",$D14)) | I14: =E14-H14 -> 43928.57 | J14: =I14/IF($C14="All locations",SUM('Additional data'!$F$5:$F$7),VLOOKUP('result II'!$C14,'Additional data'!$E$5:$F$7,2,FALSE)) -> 361.55202
C15: Hamm | D15: Winter | E15: =F15+G15 -> 14379.6 | F15: =SUMIFS('Sales data - transf.+validated'!J$5:J$35,'Sales data - transf.+validated'!$B$5:$B$35,'result II'!$C15,'Sales data - transf.+validated'!$C$5:$C$35,'result II'!$D15) -> 12499.69 | G15: =SUMIFS('Sales data - transf.+validated'!K$5:K$35,'Sales data - transf.+validated'!$B$5:$B$35,'result II'!$C15,'Sales data - transf.+validated'!$C$5:$C$35,'result II'!$D15) -> 1879.91 | H15: =SUMIFS('Sales data - transf.+validated'!$O$5:$O$35,'Sales data - transf.+validated'!$B$5:$B$35,IF($C15="All locations","*",$C15),'Sales data - transf.+validated'!$C$5:$C$35,IF($D15="All season","*",$D15)) | I15: =E15-H15 -> 5929.6 | J15: =I15/IF($C15="All locations",SUM('Additional data'!$F$5:$F$7),VLOOKUP('result II'!$C15,'Additional data'!$E$5:$F$7,2,FALSE)) -> 48.803292
C16: Hamm | D16: Summer | E16: =F16+G16 -> 92898.97 | F16: =SUMIFS('Sales data - transf.+validated'!J$5:J$35,'Sales data - transf.+validated'!$B$5:$B$35,'result II'!$C16,'Sales data - transf.+validated'!$C$5:$C$35,'result II'!$D16) -> 62599.35 | G16: =SUMIFS('Sales data - transf.+validated'!K$5:K$35,'Sales data - transf.+validated'!$B$5:$B$35,'result II'!$C16,'Sales data - transf.+validated'!$C$5:$C$35,'result II'!$D16) -> 30299.62 | H16: =SUMIFS('Sales data - transf.+validated'!$O$5:$O$35,'Sales data - transf.+validated'!$B$5:$B$35,IF($C16="All locations","*",$C16),'Sales data - transf.+validated'!$C$5:$C$35,IF($D16="All season","*",$D16)) | I16: =E16-H16 -> 37998.97 | J16: =I16/IF($C16="All locations",SUM('Additional data'!$F$5:$F$7),VLOOKUP('result II'!$C16,'Additional data'!$E$5:$F$7,2,FALSE)) -> 312.74872
C19: Locations | E19: Total items offered | F19: Winter | G19: Summer
C20: All locations | E20: =COUNTA('Sales data - transf.+validated'!$B$5:$B$35) -> 31 | F20: =COUNTIF('Sales data - transf.+validated'!$C$5:$C$35,'result II'!F$19) -> 20 | G20: =COUNTIF('Sales data - transf.+validated'!$C$5:$C$35,'result II'!G$19) -> 11
C21: Soest | E21: =COUNTIF('Sales data - transf.+validated'!$B$5:$B$35,'result II'!$C21) -> 11 | F21: =COUNTIFS('Sales data - transf.+validated'!$B$5:$B$35,'result II'!$C21,'Sales data - transf.+validated'!$C$5:$C$35,'result II'!F$19) -> 7 | G21: =COUNTIFS('Sales data - transf.+validated'!$B$5:$B$35,'result II'!$C21,'Sales data - transf.+validated'!$C$5:$C$35,'result II'!G$19) -> 4
C22: Winterberg | E22: =COUNTIF('Sales data - transf.+validated'!$B$5:$B$35,'result II'!$C22) -> 10 | F22: =COUNTIFS('Sales data - transf.+validated'!$B$5:$B$35,'result II'!$C22,'Sales data - transf.+validated'!$C$5:$C$35,'result II'!F$19) -> 7 | G22: =COUNTIFS('Sales data - transf.+validated'!$B$5:$B$35,'result II'!$C22,'Sales data - transf.+validated'!$C$5:$C$35,'result II'!G$19) -> 3
C23: Hamm | E23: =COUNTIF('Sales data - transf.+validated'!$B$5:$B$35,'result II'!$C23) -> 10 | F23: =COUNTIFS('Sales data - transf.+validated'!$B$5:$B$35,'result II'!$C23,'Sales data - transf.+validated'!$C$5:$C$35,'result II'!F$19) -> 6 | G23: =COUNTIFS('Sales data - transf.+validated'!$B$5:$B$35,'result II'!$C23,'Sales data - transf.+validated'!$C$5:$C$35,'result II'!G$19) -> 4

Sheet Additional data
A1: This sheet contains additional data
B3: Cost data October to December 2018 | E3: Store size
B4: Item | C4: Costs | E4: Location | F4: Size in m²
B5: Salomon Ski | C5: 200 | E5: Soest | F5: 130
B6: Head Ski | C6: 170 | E6: Winterberg | F6: 96
B7: Atomic Ski | C7: 300 | E7: Hamm | F7: 121.5
B8: Salomon Binding | C8: 140
B9: Head Bindings | C9: 130
B10: Lange Boots | C10: 120
B11: Head Boots | C11: 110
B12: Giant | C12: 500
B13: Yeti | C13: 450
B14: GT Bicycles | C14: 300
B15: Cannondale | C15: 2300
B16: Stöckli Ski | C16: 700
